Workbook
Name Slicer_AGENT_NAME: #N/A

Sheet Code
C6: with
C7: call_data_five_nine as
C8: (
C9: Select
C10: FBBID,
C11: Date_time_call,
C12: DISPOSITION,
C13: AGENT_NAME,
C14: AGENT_GROUP,
C15: DPD_BUCKET
C16: from analytics.credit.v_five9_call_log
C17: where
... C151: where agent_group = 'Collections Group'
C152: =-- order by call_date desc, EVENT_TIME desc -> #NAME?
C153: )
C154: {=-- Select * from agent_data} -> #NAME?
C155: -- where clean_agent_name in ('Anais Orozco') and call_date = '2026/02/04'
C156: -- order by call_date desc,event_time,CLEAN_AGENT_NAME desc, state, reason_code;
C158: ,
C159: -- CTE 3: Calculate login duration (first login to last logout)
C160: login_hours AS (
C161: SELECT
C162: CLEAN_AGENT_NAME,
C163: AGENT_GROUP,
C164: CALL_DATE,
C165: MIN(EVENT_TIME) AS FIRST_LOGIN_TIME,
C166: MAX(CASE WHEN STATE = 'Logout' THEN EVENT_TIME END) AS LAST_LOGOUT_TIME,
C167: -- Calculate logged in hours (difference between first login and last logout)
... C308: order by a.call_date desc, agent_name

Sheet Data
A1: AGENT_NAME | B1: CALL_DATE | C1: Call_month | D1: UNIQUE_ACCNTS | E1: TOTAL_DIALS | F1: PAYMENT_DISPO | G1: PTP_DISPO | H1: RPC_DISPO | I1: SETTLEMENT_DISPO | J1: THIRD_PARTY_DISPO | K1: NOT_ANSWERED_DISPO | L1: CLEAN_AGENT_NAME | M1: AGENT_GROUP | N1: CALL_DATE | O1: FIRST_LOGIN_TIME | P1: LAST_LOGOUT_TIME | Q1: LOGGED_IN_HOURS | R1: TOTAL_TRACKED_HOURS | S1: CALL_TIME_HOURS | T1: EMAIL_TIME_HOURS | U1: SMS_TIME_HOURS | V1: WRAP_TIME_HOURS | W1: IDLE_TIME_HOURS | X1: BREAK_LUNCH_HOURS | Y1: MEETING_TRAINING_HOURS | Z1: RESEARCH_TASK_HOURS | AA1: TECH_SYSTEM_HOURS | AB1: OTHER_TIME_HOURS | AC1: SUM_ALL_ACTIVITIES_HOURS | AD1: CALL_TIME_PCT | AE1: EMAIL_TIME_PCT | AF1: SMS_TIME_PCT | AG1: WRAP_TIME_PCT | AH1: IDLE_TIME_PCT | AI1: BREAK_LUNCH_PCT | AJ1: MEETING_TRAINING_PCT | AK1: RESEARCH_TASK_PCT | AL1: TECH_SYSTEM_PCT | AM1: OTHER_TIME_PCT | AN1: week_day | AO1: Call_day
A2: Anais Orozco | B2: 46057 | C2: =EOMONTH(B2,0) -> 46081 | D2: 52 | E2: 132 | F2: 3 | G2: 6 | H2: 11 | I2: 2 | J2: 9 | K2: 70 | L2: Anais Orozco | M2: Collections Group | N2: 46057 | O2: 0.58391204 | P2: 0.95898148 | Q2: 9 | R2: 8.11 | S2: 3.21 | T2: 0.39 | U2: 0 | V2: 0.48 | W2: 3.35 | X2: 0.68 | Y2: 0 | Z2: 0 | AA2: 0 | AB2: 0.01 | AC2: 8.11 | AD2: 39.52 | AE2: 4.85 | AF2: 0 | AG2: 5.88 | AH2: 41.24 | AI2: 8.34 | AJ2: 0 | AK2: 0 | AL2: 0 | AM2: 0.17 | AN2: =WEEKDAY(B2,1) -> 4 | AO2: =VLOOKUP(AN2,$AY$2:$AZ$8,2,FALSE) -> Wednesday | AY2: 1 | AZ2: Sunday
A3: Derice Warnsley | B3: 46057 | C3: =EOMONTH(B3,0) -> 46081 | D3: 65 | E3: 159 | F3: 12 | G3: 8 | H3: 26 | I3: 0 | J3: 7 | K3: 65 | L3: Derice Warnsley | M3: Collections Group | N3: 46057 | O3: 0.58365741 | P3: 0.95836806 | Q3: 9 | R3: 8.99 | S3: 3.83 | T3: 0.24 | U3: 0 | V3: 0.12 | W3: 3.3 | X3: 1.5 | Y3: 0 | Z3: 0 | AA3: 0 | AB3: 0 | AC3: 8.99 | AD3: 42.58 | AE3: 2.65 | AF3: 0 | AG3: 1.31 | AH3: 36.69 | AI3: 16.72 | AJ3: 0 | AK3: 0 | AL3: 0 | AM3: 0.05 | AN3: =WEEKDAY(B3,1) -> 4 | AO3: =VLOOKUP(AN3,$AY$2:$AZ$8,2,FALSE) -> Wednesday | AY3: 2 | AZ3: Monday
A4: Isiah Thomas | B4: 46057 | C4: =EOMONTH(B4,0) -> 46081 | D4: 67 | E4: 179 | F4: 3 | G4: 2 | H4: 18 | I4: 0 | J4: 0 | K4: 107 | L4: Isiah Thomas | M4: Collections Group | N4: 46057 | O4: 0.58369213 | P4: 0.95835648 | Q4: 9 | R4: 8.99 | S4: 2.57 | T4: 0.59 | U4: 0 | V4: 0.4 | W4: 3.89 | X4: 1.52 | Y4: 0 | Z4: 0 | AA4: 0 | AB4: 0 | AC4: 8.99 | AD4: 28.63 | AE4: 6.6 | AF4: 0 | AG4: 4.49 | AH4: 43.28 | AI4: 16.96 | AJ4: 0 | AK4: 0 | AL4: 0 | AM4: 0.04 | AN4: =WEEKDAY(B4,1) -> 4 | AO4: =VLOOKUP(AN4,$AY$2:$AZ$8,2,FALSE) -> Wednesday | AY4: 3 | AZ4: Tuesday
A5: Jerrod Coleman | B5: 46057 | C5: =EOMONTH(B5,0) -> 46081 | D5: 65 | E5: 150 | F5: 6 | G5: 10 | H5: 14 | I5: 0 | J5: 5 | K5: 60 | L5: Jerrod Coleman | M5: Collections Group | N5: 46057 | O5: 0.58333333 | P5: 0.95697917 | Q5: 8.97 | R5: 8.97 | S5: 3.4 | T5: 0.32 | U5: 0 | V5: 0.37 | W5: 3.47 | X5: 1.4 | Y5: 0 | Z5: 0 | AA5: 0 | AB5: 0 | AC5: 8.97 | AD5: 37.97 | AE5: 3.53 | AF5: 0 | AG5: 4.07 | AH5: 38.75 | AI5: 15.62 | AJ5: 0 | AK5: 0 | AL5: 0 | AM5: 0.05 | AN5: =WEEKDAY(B5,1) -> 4 | AO5: =VLOOKUP(AN5,$AY$2:$AZ$8,2,FALSE) -> Wednesday | AY5: 4 | AZ5: Wednesday
A6: Rosette Rwabugahya | B6: 46057 | C6: =EOMONTH(B6,0) -> 46081 | D6: 2 | E6: 2 | F6: 0 | G6: 0 | H6: 0 | I6: 0 | J6: 0 | K6: 0 | L6: Rosette Rwabugahya | M6: Collections Group | N6: 46057 | O6: 0.88861111 | P6: 0.9077662 | Q6: 0.47 | R6: 0.46 | S6: 0.45 | T6: 0 | U6: 0 | V6: 0.01 | W6: 0 | X6: 0 | Y6: 0 | Z6: 0 | AA6: 0 | AB6: 0.01 | AC6: 0.46 | AD6: 97.46 | AE6: 0 | AF6: 0 | AG6: 1.15 | AH6: 0 | AI6: 0 | AJ6: 0 | AK6: 0 | AL6: 0 | AM6: 1.39 | AN6: =WEEKDAY(B6,1) -> 4 | AO6: =VLOOKUP(AN6,$AY$2:$AZ$8,2,FALSE) -> Wednesday | AY6: 5 | AZ6: Thursday
A7: Sabigh Masood | B7: 46057 | C7: =EOMONTH(B7,0) -> 46081 | D7: 63 | E7: 167 | F7: 4 | G7: 8 | H7: 23 | I7: 0 | J7: 2 | K7: 85 | L7: Sabigh Masood | M7: Collections Group | N7: 46057 | O7: 0.58329861 | P7: 0.95902778 | Q7: 9.03 | R7: 9.02 | S7: 2.71 | T7: 0.2 | U7: 0 | V7: 0.58 | W7: 4.08 | X7: 1.45 | Y7: 0 | Z7: 0 | AA7: 0 | AB7: 0 | AC7: 9.02 | AD7: 30.1 | AE7: 2.18 | AF7: 0 | AG7: 6.4 | AH7: 45.2 | AI7: 16.08 | AJ7: 0 | AK7: 0 | AL7: 0 | AM7: 0.05 | AN7: =WEEKDAY(B7,1) -> 4 | AO7: =VLOOKUP(AN7,$AY$2:$AZ$8,2,FALSE) -> Wednesday | AY7: 6 | AZ7: Friday
B8: 46057 | C8: =EOMONTH(B8,0) -> 46081 | D8: 1307 | E8: 0 | F8: 0 | G8: 0 | H8: 0 | I8: 0 | J8: 0 | K8: 0 | AN8: =WEEKDAY(B8,1) -> 4 | AO8: =VLOOKUP(AN8,$AY$2:$AZ$8,2,FALSE) -> Wednesday | AY8: 7 | AZ8: Saturday
A9: Anais Orozco | B9: 46056 | C9: =EOMONTH(B9,0) -> 46081 | D9: 55 | E9: 131 | F9: 13 | G9: 6 | H9: 19 | I9: 1 | J9: 9 | K9: 55 | L9: Anais Orozco | M9: Collections Group | N9: 46056 | O9: 0.58475694 | P9: 0.95847222 | Q9: 8.97 | R9: 8.97 | S9: 3.62 | T9: 0.44 | U9: 0 | V9: 0.5 | W9: 2.89 | X9: 1.5 | Y9: 0 | Z9: 0 | AA9: 0 | AB9: 0 | AC9: 8.97 | AD9: 40.39 | AE9: 4.91 | AF9: 0 | AG9: 5.62 | AH9: 32.25 | AI9: 16.78 | AJ9: 0 | AK9: 0 | AL9: 0 | AM9: 0.05 | AN9: =WEEKDAY(B9,1) -> 3 | AO9: =VLOOKUP(AN9,$AY$2:$AZ$8,2,FALSE) -> Tuesday
A10: Derice Warnsley | B10: 46056 | C10: =EOMONTH(B10,0) -> 46081 | D10: 70 | E10: 160 | F10: 33 | G10: 13 | H10: 19 | I10: 0 | J10: 2 | K10: 70 | L10: Derice Warnsley | M10: Collections Group | N10: 46056 | O10: 0.58236111 | P10: 0.95842593 | Q10: 9.03 | R10: 9 | S10: 3.31 | T10: 0.21 | U10: 0 | V10: 0.15 | W10: 3.79 | X10: 1.51 | Y10: 0 | Z10: 0 | AA10: 0 | AB10: 0.04 | AC10: 9 | AD10: 36.79 | AE10: 2.29 | AF10: 0 | AG10: 1.66 | AH10: 42.11 | AI10: 16.73 | AJ10: 0 | AK10: 0 | AL10: 0 | AM10: 0.43 | AN10: =WEEKDAY(B10,1) -> 3 | AO10: =VLOOKUP(AN10,$AY$2:$AZ$8,2,FALSE) -> Tuesday
A11: Isiah Thomas | B11: 46056 | C11: =EOMONTH(B11,0) -> 46081 | D11: 62 | E11: 143 | F11: 18 | G11: 7 | H11: 16 | I11: 0 | J11: 1 | K11: 74 | L11: Isiah Thomas | M11: Collections Group | N11: 46056 | O11: 0.58391204 | P11: 0.95853009 | Q11: 9 | R11: 8.95 | S11: 2.99 | T11: 0.66 | U11: 0 | V11: 0.38 | W11: 3.38 | X11: 1.53 | Y11: 0 | Z11: 0 | AA11: 0 | AB11: 0.01 | AC11: 8.95 | AD11: 33.37 | AE11: 7.37 | AF11: 0 | AG11: 4.29 | AH11: 37.82 | AI11: 17.07 | AJ11: 0 | AK11: 0 | AL11: 0 | AM11: 0.07 | AN11: =WEEKDAY(B11,1) -> 3 | AO11: =VLOOKUP(AN11,$AY$2:$AZ$8,2,FALSE) -> Tuesday
A12: Jerrod Coleman | B12: 46056 | C12: =EOMONTH(B12,0) -> 46081 | D12: 59 | E12: 118 | F12: 13 | G12: 14 | H12: 7 | I12: 0 | J12: 5 | K12: 47 | L12: Jerrod Coleman | M12: Collections Group | N12: 46056 | O12: 0.58318287 | P12: 0.95777778 | Q12: 9 | R12: 8.11 | S12: 3.17 | T12: 1.39 | U12: 0 | V12: 0.29 | W12: 2.68 | X12: 0.55 | Y12: 0 | Z12: 0 | AA12: 0 | AB12: 0.01 | AC12: 8.11 | AD12: 39.13 | AE12: 17.14 | AF12: 0 | AG12: 3.63 | AH12: 33.12 | AI12: 6.81 | AJ12: 0 | AK12: 0 | AL12: 0 | AM12: 0.17 | AN12: =WEEKDAY(B12,1) -> 3 | AO12: =VLOOKUP(AN12,$AY$2:$AZ$8,2,FALSE) -> Tuesday
A13: Sabigh Masood | B13: 46056 | C13: =EOMONTH(B13,0) -> 46081 | D13: 70 | E13: 207 | F13: 26 | G13: 15 | H13: 34 | I13: 0 | J13: 1 | K13: 76 | L13: Sabigh Masood | M13: Collections Group | N13: 46056 | O13: 0.58347222 | P13: 0.95979167 | Q13: 9.03 | R13: 9.03 | S13: 2.97 | T13: 0.09 | U13: 0 | V13: 0.64 | W13: 3.84 | X13: 1.48 | Y13: 0 | Z13: 0 | AA13: 0.02 | AB13: 0 | AC13: 9.03 | AD13: 32.85 | AE13: 0.95 | AF13: 0 | AG13: 7.04 | AH13: 42.53 | AI13: 16.41 | AJ13: 0 | AK13: 0 | AL13: 0.17 | AM13: 0.04 | AN13: =WEEKDAY(B13,1) -> 3 | AO13: =VLOOKUP(AN13,$AY$2:$AZ$8,2,FALSE) -> Tuesday
B14: 46056 | C14: =EOMONTH(B14,0) -> 46081 | D14: 1412 | E14: 0 | F14: 0 | G14: 0 | H14: 0 | I14: 0 | J14: 0 | K14: 0 | AN14: =WEEKDAY(B14,1) -> 3 | AO14: =VLOOKUP(AN14,$AY$2:$AZ$8,2,FALSE) -> Tuesday
A15: Derice Warnsley | B15: 46055 | C15: =EOMONTH(B15,0) -> 46081 | D15: 83 | E15: 203 | F15: 18 | G15: 9 | H15: 23 | I15: 1 | J15: 1 | K15: 104 | L15: Derice Warnsley | M15: Collections Group | N15: 46055 | O15: 0.58358796 | P15: 0.96056713 | Q15: 9.05 | R15: 9.05 | S15: 3.5 | T15: 0.03 | U15: 0 | V15: 0.15 | W15: 3.86 | X15: 1.5 | Y15: 0 | Z15: 0 | AA15: 0 | AB15: 0.01 | AC15: 9.05 | AD15: 38.68 | AE15: 0.38 | AF15: 0 | AG15: 1.63 | AH15: 42.67 | AI15: 16.54 | AJ15: 0 | AK15: 0 | AL15: 0 | AM15: 0.1 | AN15: =WEEKDAY(B15,1) -> 2 | AO15: =VLOOKUP(AN15,$AY$2:$AZ$8,2,FALSE) -> Monday
A16: Isiah Thomas | B16: 46055 | C16: =EOMONTH(B16,0) -> 46081 | D16: 68 | E16: 161 | F16: 12 | G16: 5 | H16: 5 | I16: 0 | J16: 1 | K16: 94 | L16: Isiah Thomas | M16: Collections Group | N16: 46055 | O16: 0.58387731 | P16: 0.95840278 | Q16: 9 | R16: 9.02 | S16: 2.61 | T16: 0.51 | U16: 0 | V16: 0.26 | W16: 3.14 | X16: 1.51 | Y16: 0.99 | Z16: 0 | AA16: 0 | AB16: 0 | AC16: 9.02 | AD16: 28.91 | AE16: 5.64 | AF16: 0 | AG16: 2.88 | AH16: 34.86 | AI16: 16.73 | AJ16: 10.93 | AK16: 0 | AL16: 0 | AM16: 0.05 | AN16: =WEEKDAY(B16,1) -> 2 | AO16: =VLOOKUP(AN16,$AY$2:$AZ$8,2,FALSE) -> Monday
A17: Rakesh Rajendran | B17: 46055 | C17: =EOMONTH(B17,0) -> 46081 | D17: 1 | E17: 1 | F17: 0 | G17: 0 | H17: 0 | I17: 0 | J17: 0 | K17: 0 | AN17: =WEEKDAY(B17,1) -> 2 | AO17: =VLOOKUP(AN17,$AY$2:$AZ$8,2,FALSE) -> Monday
A18: Rosette Rwabugahya | B18: 46055 | C18: =EOMONTH(B18,0) -> 46081 | D18: 2 | E18: 2 | F18: 0 | G18: 0 | H18: 2 | I18: 0 | J18: 0 | K18: 0 | L18: Rosette Rwabugahya | M18: Collections Group | N18: 46055 | O18: 0.71134259 | P18: 0.90165509 | Q18: 4.57 | R18: 4.57 | S18: 4.55 | T18: 0 | U18: 0 | V18: 0.01 | W18: 0 | X18: 0 | Y18: 0 | Z18: 0 | AA18: 0 | AB18: 0 | AC18: 4.57 | AD18: 99.61 | AE18: 0 | AF18: 0 | AG18: 0.29 | AH18: 0 | AI18: 0 | AJ18: 0 | AK18: 0 | AL18: 0 | AM18: 0.1 | AN18: =WEEKDAY(B18,1) -> 2 | AO18: =VLOOKUP(AN18,$AY$2:$AZ$8,2,FALSE) -> Monday
A19: Sabigh Masood | B19: 46055 | C19: =EOMONTH(B19,0) -> 46081 | D19: 78 | E19: 179 | F19: 14 | G19: 4 | H19: 15 | I19: 0 | J19: 0 | K19: 85 | L19: Sabigh Masood | M19: Collections Group | N19: 46055 | O19: 0.58296296 | P19: 0.95894676 | Q19: 9.02 | R19: 9.02 | S19: 3.4 | T19: 0.14 | U19: 0 | V19: 0.51 | W19: 3.72 | X19: 1.25 | Y19: 0 | Z19: 0 | AA19: 0 | AB19: 0 | AC19: 9.02 | AD19: 37.63 | AE19: 1.55 | AF19: 0 | AG19: 5.7 | AH19: 41.18 | AI19: 13.89 | AJ19: 0 | AK19: 0 | AL19: 0 | AM19: 0.05 | AN19: =WEEKDAY(B19,1) -> 2 | AO19: =VLOOKUP(AN19,$AY$2:$AZ$8,2,FALSE) -> Monday
B20: 46055 | C20: =EOMONTH(B20,0) -> 46081 | D20: 1191 | E20: 0 | F20: 0 | G20: 0 | H20: 0 | I20: 0 | J20: 0 | K20: 0 | AN20: =WEEKDAY(B20,1) -> 2 | AO20: =VLOOKUP(AN20,$AY$2:$AZ$8,2,FALSE) -> Monday
A21: Anais Orozco | B21: 46052 | C21: =EOMONTH(B21,0) -> 46053 | D21: 54 | E21: 118 | F21: 4 | G21: 1 | H21: 7 | I21: 0 | J21: 3 | K21: 63 | L21: Anais Orozco | M21: Collections Group | N21: 46052 | O21: 0.58216435 | P21: 0.95842593 | Q21: 9.03 | R21: 8.12 | S21: 2.63 | T21: 0.28 | U21: 0 | V21: 0.31 | W21: 3.73 | X21: 0.6 | Y21: 0.53 | Z21: 0 | AA21: 0 | AB21: 0.04 | AC21: 8.12 | AD21: 32.39 | AE21: 3.41 | AF21: 0 | AG21: 3.84 | AH21: 45.97 | AI21: 7.34 | AJ21: 6.51 | AK21: 0 | AL21: 0 | AM21: 0.53 | AN21: =WEEKDAY(B21,1) -> 6 | AO21: =VLOOKUP(AN21,$AY$2:$AZ$8,2,FALSE) -> Friday
A22: Derice Warnsley | B22: 46052 | C22: =EOMONTH(B22,0) -> 46053 | D22: 77 | E22: 153 | F22: 13 | G22: 8 | H22: 28 | I22: 2 | J22: 0 | K22: 74 | L22: Derice Warnsley | M22: Collections Group | N22: 46052 | O22: 0.5830787 | P22: 0.95842593 | Q22: 9.02 | R22: 9.01 | S22: 3.37 | T22: 0.21 | U22: 0 | V22: 0.12 | W22: 3.84 | X22: 1.45 | Y22: 0 | Z22: 0 | AA22: 0 | AB22: 0.01 | AC22: 9.01 | AD22: 37.46 | AE22: 2.31 | AF22: 0 | AG22: 1.33 | AH22: 42.68 | AI22: 16.14 | AJ22: 0 | AK22: 0 | AL22: 0 | AM22: 0.08 | AN22: =WEEKDAY(B22,1) -> 6 | AO22: =VLOOKUP(AN22,$AY$2:$AZ$8,2,FALSE) -> Friday
A23: Isiah Thomas | B23: 46052 | C23: =EOMONTH(B23,0) -> 46053 | D23: 62 | E23: 134 | F23: 8 | G23: 9 | H23: 8 | I23: 1 | J23: 3 | K23: 72 | L23: Isiah Thomas | M23: Collections Group | N23: 46052 | O23: 0.58329861 | P23: 0.95840278 | Q23: 9.02 | R23: 9 | S23: 2.63 | T23: 0.31 | U23: 0 | V23: 0.33 | W23: 4.21 | X23: 1.51 | Y23: 0 | Z23: 0 | AA23: 0 | AB23: 0 | AC23: 9 | AD23: 29.19 | AE23: 3.49 | AF23: 0 | AG23: 3.68 | AH23: 46.77 | AI23: 16.83 | AJ23: 0 | AK23: 0 | AL23: 0 | AM23: 0.04 | AN23: =WEEKDAY(B23,1) -> 6 | AO23: =VLOOKUP(AN23,$AY$2:$AZ$8,2,FALSE) -> Friday
A24: Jerrod Coleman | B24: 46052 | C24: =EOMONTH(B24,0) -> 46053 | D24: 34 | E24: 58 | F24: 1 | G24: 3 | H24: 5 | I24: 0 | J24: 5 | K24: 29 | L24: Jerrod Coleman | M24: Collections Group | N24: 46052 | O24: 0.58324074 | P24: 0.77041667 | Q24: 4.5 | R24: 4.49 | S24: 1.36 | T24: 0.58 | U24: 0 | V24: 0.12 | W24: 2.12 | X24: 0.3 | Y24: 0 | Z24: 0 | AA24: 0 | AB24: 0 | AC24: 4.49 | AD24: 30.22 | AE24: 12.98 | AF24: 0 | AG24: 2.68 | AH24: 47.28 | AI24: 6.75 | AJ24: 0 | AK24: 0 | AL24: 0 | AM24: 0.09 | AN24: =WEEKDAY(B24,1) -> 6 | AO24: =VLOOKUP(AN24,$AY$2:$AZ$8,2,FALSE) -> Friday
A25: Rakesh Rajendran | B25: 46052 | C25: =EOMONTH(B25,0) -> 46053 | D25: 1 | E25: 4 | F25: 0 | G25: 0 | H25: 0 | I25: 0 | J25: 1 | K25: 0 | AN25: =WEEKDAY(B25,1) -> 6 | AO25: =VLOOKUP(AN25,$AY$2:$AZ$8,2,FALSE) -> Friday
A26: Sabigh Masood | B26: 46052 | C26: =EOMONTH(B26,0) -> 46053 | D26: 48 | E26: 124 | F26: 8 | G26: 5 | H26: 6 | I26: 1 | J26: 0 | K26: 70 | L26: Sabigh Masood | M26: Collections Group | N26: 46052 | O26: 0.58356481 | P26: 0.95894676 | Q26: 9 | R26: 9.01 | S26: 1.52 | T26: 0.17 | U26: 0 | V26: 0.59 | W26: 4.08 | X26: 1.92 | Y26: 0.71 | Z26: 0 | AA26: 0.02 | AB26: 0 | AC26: 9.01 | AD26: 16.83 | AE26: 1.91 | AF26: 0 | AG26: 6.57 | AH26: 45.27 | AI26: 21.29 | AJ26: 7.91 | AK26: 0 | AL26: 0.19 | AM26: 0.03 | AN26: =WEEKDAY(B26,1) -> 6 | AO26: =VLOOKUP(AN26,$AY$2:$AZ$8,2,FALSE) -> Friday
B27: 46052 | C27: =EOMONTH(B27,0) -> 46053 | D27: 1231 | E27: 0 | F27: 0 | G27: 0 | H27: 0 | I27: 0 | J27: 0 | K27: 0 | AN27: =WEEKDAY(B27,1) -> 6 | AO27: =VLOOKUP(AN27,$AY$2:$AZ$8,2,FALSE) -> Friday
A28: Anais Orozco | B28: 46051 | C28: =EOMONTH(B28,0) -> 46053 | D28: 36 | E28: 42 | F28: 3 | G28: 4 | H28: 3 | I28: 0 | J28: 1 | K28: 1 | L28: Anais Orozco | M28: Collections Group | N28: 46051 | O28: 0.58347222 | P28: 0.95834491 | Q28: 9 | R28: 9 | S28: 3.49 | T28: 0.31 | U28: 0 | V28: 0.28 | W28: 1.95 | X28: 1.45 | Y28: 1.52 | Z28: 0 | AA28: 0 | AB28: 0 | AC28: 9 | AD28: 38.79 | AE28: 3.43 | AF28: 0 | AG28: 3.09 | AH28: 21.65 | AI28: 16.12 | AJ28: 16.88 | AK28: 0 | AL28: 0 | AM28: 0.05 | AN28: =WEEKDAY(B28,1) -> 5 | AO28: =VLOOKUP(AN28,$AY$2:$AZ$8,2,FALSE) -> Thursday
A29: Derice Warnsley | B29: 46051 | C29: =EOMONTH(B29,0) -> 46053 | D29: 70 | E29: 78 | F29: 4 | G29: 1 | H29: 9 | I29: 1 | J29: 1 | K29: 1 | L29: Derice Warnsley | M29: Collections Group | N29: 46051 | O29: 0.5834838 | P29: 0.95994213 | Q29: 9.03 | R29: 9.04 | S29: 2.68 | T29: 0.1 | U29: 0 | V29: 0.16 | W29: 2.95 | X29: 1.41 | Y29: 1.73 | Z29: 0 | AA29: 0 | AB29: 0.01 | AC29: 9.04 | AD29: 29.68 | AE29: 1.1 | AF29: 0 | AG29: 1.75 | AH29: 32.66 | AI29: 15.56 | AJ29: 19.18 | AK29: 0 | AL29: 0 | AM29: 0.06 | AN29: =WEEKDAY(B29,1) -> 5 | AO29: =VLOOKUP(AN29,$AY$2:$AZ$8,2,FALSE) -> Thursday
A30: Isiah Thomas | B30: 46051 | C30: =EOMONTH(B30,0) -> 46053 | D30: 65 | E30: 82 | F30: 5 | G30: 1 | H30: 7 | I30: 0 | J30: 0 | K30: 9 | L30: Isiah Thomas | M30: Collections Group | N30: 46051 | O30: 0.5833912 | P30: 0.9584375 | Q30: 9 | R30: 9 | S30: 1.55 | T30: 0.41 | U30: 0 | V30: 0.42 | W30: 3.54 | X30: 1.53 | Y30: 1.5 | Z30: 0 | AA30: 0.04 | AB30: 0 | AC30: 9 | AD30: 17.24 | AE30: 4.6 | AF30: 0 | AG30: 4.71 | AH30: 39.36 | AI30: 16.99 | AJ30: 16.68 | AK30: 0 | AL30: 0.4 | AM30: 0.03 | AN30: =WEEKDAY(B30,1) -> 5 | AO30: =VLOOKUP(AN30,$AY$2:$AZ$8,2,FALSE) -> Thursday
A31: Jerrod Coleman | B31: 46051 | C31: =EOMONTH(B31,0) -> 46053 | D31: 73 | E31: 81 | F31: 7 | G31: 5 | H31: 10 | I31: 0 | J31: 3 | K31: 0 | L31: Jerrod Coleman | M31: Collections Group | N31: 46051 | O31: 0.58325231 | P31: 0.95841435 | Q31: 9.02 | R31: 9 | S31: 2.05 | T31: 0.6 | U31: 0 | V31: 0.29 | W31: 3.12 | X31: 1.46 | Y31: 1.48 | Z31: 0 | AA31: 0 | AB31: 0.01 | AC31: 9 | AD31: 22.81 | AE31: 6.64 | AF31: 0 | AG31: 3.23 | AH31: 34.67 | AI31: 16.19 | AJ31: 16.4 | AK31: 0 | AL31: 0 | AM31: 0.06 | AN31: =WEEKDAY(B31,1) -> 5 | AO31: =VLOOKUP(AN31,$AY$2:$AZ$8,2,FALSE) -> Thursday
A32: Sabigh Masood | B32: 46051 | C32: =EOMONTH(B32,0) -> 46053 | D32: 44 | E32: 62 | F32: 3 | G32: 4 | H32: 8 | I32: 0 | J32: 0 | K32: 0 | L32: Sabigh Masood | M32: Collections Group | N32: 46051 | O32: 0.58293981 | P32: 0.9590625 | Q32: 9.03 | R32: 9.02 | S32: 2.04 | T32: 0.1 | U32: 0 | V32: 0.66 | W32: 3.27 | X32: 1.45 | Y32: 1.5 | Z32: 0 | AA32: 0 | AB32: 0.01 | AC32: 9.02 | AD32: 22.63 | AE32: 1.14 | AF32: 0 | AG32: 7.27 | AH32: 36.28 | AI32: 16.02 | AJ32: 16.61 | AK32: 0 | AL32: 0 | AM32: 0.06 | AN32: =WEEKDAY(B32,1) -> 5 | AO32: =VLOOKUP(AN32,$AY$2:$AZ$8,2,FALSE) -> Thursday
A33: Anais Orozco | B33: 46050 | C33: =EOMONTH(B33,0) -> 46053 | D33: 16 | E33: 29 | F33: 6 | G33: 1 | H33: 6 | I33: 0 | J33: 6 | K33: 6 | L33: Anais Orozco | M33: Collections Group | N33: 46050 | O33: 0.58263889 | P33: 0.7140162 | Q33: 3.15 | R33: 3.13 | S33: 1.45 | T33: 0.3 | U33: 0 | V33: 0.13 | W33: 0.94 | X33: 0.28 | Y33: 0 | Z33: 0 | AA33: 0 | AB33: 0.03 | AC33: 3.13 | AD33: 46.35 | AE33: 9.65 | AF33: 0 | AG33: 4 | AH33: 29.97 | AI33: 9 | AJ33: 0 | AK33: 0 | AL33: 0 | AM33: 1.03 | AN33: =WEEKDAY(B33,1) -> 4 | AO33: =VLOOKUP(AN33,$AY$2:$AZ$8,2,FALSE) -> Wednesday
A34: Derice Warnsley | B34: 46050 | C34: =EOMONTH(B34,0) -> 46053 | D34: 67 | E34: 147 | F34: 12 | G34: 2 | H34: 12 | I34: 4 | J34: 1 | K34: 76 | L34: Derice Warnsley | M34: Collections Group | N34: 46050 | O34: 0.58241898 | P34: 0.95846065 | Q34: 9.03 | R34: 9.02 | S34: 2.84 | T34: 0.17 | U34: 0 | V34: 0.09 | W34: 4.19 | X34: 1.48 | Y34: 0.23 | Z34: 0 | AA34: 0 | AB34: 0.03 | AC34: 9.02 | AD34: 31.51 | AE34: 1.84 | AF34: 0 | AG34: 0.94 | AH34: 46.42 | AI34: 16.39 | AJ34: 2.52 | AK34: 0 | AL34: 0 | AM34: 0.36 | AN34: =WEEKDAY(B34,1) -> 4 | AO34: =VLOOKUP(AN34,$AY$2:$AZ$8,2,FALSE) -> Wednesday
A35: Isiah Thomas | B35: 46050 | C35: =EOMONTH(B35,0) -> 46053 | D35: 66 | E35: 151 | F35: 15 | G35: 7 | H35: 10 | I35: 0 | J35: 2 | K35: 75 | L35: Isiah Thomas | M35: Collections Group | N35: 46050 | O35: 0.58359954 | P35: 0.96238426 | Q35: 9.08 | R35: 9.09 | S35: 3.1 | T35: 0.56 | U35: 0 | V35: 0.34 | W35: 3.5 | X35: 1.57 | Y35: 0 | Z35: 0 | AA35: 0 | AB35: 0.01 | AC35: 9.09 | AD35: 34.14 | AE35: 6.18 | AF35: 0 | AG35: 3.79 | AH35: 38.54 | AI35: 17.26 | AJ35: 0 | AK35: 0 | AL35: 0 | AM35: 0.09 | AN35: =WEEKDAY(B35,1) -> 4 | AO35: =VLOOKUP(AN35,$AY$2:$AZ$8,2,FALSE) -> Wednesday
A36: Jerrod Coleman | B36: 46050 | C36: =EOMONTH(B36,0) -> 46053 | D36: 66 | E36: 144 | F36: 14 | G36: 14 | H36: 16 | I36: 0 | J36: 13 | K36: 52 | L36: Jerrod Coleman | M36: Collections Group | N36: 46050 | O36: 0.58319444 | P36: 0.95700231 | Q36: 8.98 | R36: 8.97 | S36: 3.48 | T36: 0.54 | U36: 0 | V36: 0.29 | W36: 3.35 | X36: 1.29 | Y36: 0 | Z36: 0 | AA36: 0 | AB36: 0 | AC36: 8.97 | AD36: 38.84 | AE36: 6.06 | AF36: 0 | AG36: 3.27 | AH36: 37.36 | AI36: 14.43 | AJ36: 0 | AK36: 0 | AL36: 0 | AM36: 0.04 | AN36: =WEEKDAY(B36,1) -> 4 | AO36: =VLOOKUP(AN36,$AY$2:$AZ$8,2,FALSE) -> Wednesday
A37: Sabigh Masood | B37: 46050 | C37: =EOMONTH(B37,0) -> 46053 | D37: 68 | E37: 176 | F37: 7 | G37: 6 | H37: 13 | I37: 0 | J37: 2 | K37: 95 | L37: Sabigh Masood | M37: Collections Group | N37: 46050 | O37: 0.58325231 | P37: 0.95965278 | Q37: 9.03 | R37: 9.03 | S37: 1.96 | T37: 0.16 | U37: 0 | V37: 0.71 | W37: 3.95 | X37: 1.43 | Y37: 0.78 | Z37: 0 | AA37: 0.04 | AB37: 0 | AC37: 9.03 | AD37: 21.69 | AE37: 1.79 | AF37: 0 | AG37: 7.86 | AH37: 43.78 | AI37: 15.79 | AJ37: 8.6 | AK37: 0 | AL37: 0.46 | AM37: 0.04 | AN37: =WEEKDAY(B37,1) -> 4 | AO37: =VLOOKUP(AN37,$AY$2:$AZ$8,2,FALSE) -> Wednesday
B38: 46050 | C38: =EOMONTH(B38,0) -> 46053 | D38: 1312 | E38: 0 | F38: 0 | G38: 0 | H38: 0 | I38: 0 | J38: 0 | K38: 0 | AN38: =WEEKDAY(B38,1) -> 4 | AO38: =VLOOKUP(AN38,$AY$2:$AZ$8,2,FALSE) -> Wednesday
A39: Anais Orozco | B39: 46049 | C39: =EOMONTH(B39,0) -> 46053 | D39: 58 | E39: 164 | F39: 12 | G39: 22 | H39: 19 | I39: 0 | J39: 4 | K39: 69 | L39: Anais Orozco | M39: Collections Group | N39: 46049 | O39: 0.58341435 | P39: 0.9584375 | Q39: 9 | R39: 8.09 | S39: 3.35 | T39: 0.32 | U39: 0 | V39: 0.67 | W39: 3.05 | X39: 0.58 | Y39: 0 | Z39: 0 | AA39: 0.07 | AB39: 0.05 | AC39: 8.09 | AD39: 41.44 | AE39: 3.98 | AF39: 0 | AG39: 8.34 | AH39: 37.65 | AI39: 7.18 | AJ39: 0 | AK39: 0 | AL39: 0.83 | AM39: 0.58 | AN39: =WEEKDAY(B39,1) -> 3 | AO39: =VLOOKUP(AN39,$AY$2:$AZ$8,2,FALSE) -> Tuesday
A40: Derice Warnsley | B40: 46049 | C40: =EOMONTH(B40,0) -> 46053 | D40: 73 | E40: 184 | F40: 14 | G40: 11 | H40: 14 | I40: 0 | J40: 5 | K40: 92 | L40: Derice Warnsley | M40: Collections Group | N40: 46049 | O40: 0.5834838 | P40: 0.96097222 | Q40: 9.05 | R40: 9.04 | S40: 3.28 | T40: 0.2 | U40: 0 | V40: 0.11 | W40: 3.93 | X40: 1.49 | Y40: 0 | Z40: 0 | AA40: 0 | AB40: 0.02 | AC40: 9.04 | AD40: 36.35 | AE40: 2.24 | AF40: 0 | AG40: 1.24 | AH40: 43.48 | AI40: 16.49 | AJ40: 0 | AK40: 0 | AL40: 0 | AM40: 0.2 | AN40: =WEEKDAY(B40,1) -> 3 | AO40: =VLOOKUP(AN40,$AY$2:$AZ$8,2,FALSE) -> Tuesday
...

Sheet Pivots
C3: UNIQUE_ACCNTS | D3: (Multiple Items) | P3: UNIQUE_ACCNTS | Q3: (Multiple Items)
C5: CALL_DATE | D5: Call_day | E5: Sum of UNIQUE_ACCNTS | F5: Sum of Total Contacted | G5: Average of TOTAL_TRACKED_HOURS | H5: Average of CALL_TIME_HOURS | I5: Average of EMAIL_TIME_HOURS | J5: Average of WRAP_TIME_HOURS | K5: Average of MEETING_TRAINING_HOURS | L5: Average of BREAK_LUNCH_HOURS | M5: Average of IDLE_TIME_HOURS | P5: Call_month | Q5: Sum of UNIQUE_ACCNTS | R5: Sum of Total Contacted | S5: Average of TOTAL_TRACKED_HOURS | T5: Average of CALL_TIME_HOURS | U5: Average of EMAIL_TIME_HOURS | V5: Average of WRAP_TIME_HOURS | W5: Average of MEETING_TRAINING_HOURS | X5: Average of BREAK_LUNCH_HOURS | Y5: Average of IDLE_TIME_HOURS
C6: 46057 | D6: Wednesday | E6: 1619 | F6: 179 | G6: 8.816 | H6: 3.144 | I6: 0.348 | J6: 0.39 | K6: 0 | L6: 1.31 | M6: 3.618 | P6: 46081 | Q6: 4767 | R6: 559 | S6: 8.8638462 | T6: 3.1761538 | U6: 0.40076923 | V6: 0.37153846 | W6: 0.076153846 | X6: 1.3369231 | Y6: 3.4915385
C7: 46056 | D7: Tuesday | E7: 1728 | F7: 272 | G7: 8.812 | H7: 3.212 | I7: 0.558 | J7: 0.392 | K7: 0 | L7: 1.314 | M7: 3.316 | P7: 46053 | Q7: 22226 | R7: 2734 | S7: 8.6537634 | T7: 2.5906452 | U7: 0.32010753 | V7: 0.37236559 | W7: 0.47612903 | X7: 1.3048387 | Y7: 3.5693548
C8: 46055 | D8: Monday | E8: 1420 | F8: 108 | G8: 9.03 | H8: 3.17 | I8: 0.22666667 | J8: 0.30666667 | K8: 0.33 | L8: 1.42 | M8: 3.5733333 | P8: 46022 | Q8: 20515 | R8: 2272 | S8: 8.425625 | T8: 2.092625 | U8: 0.31475 | V8: 0.385625 | W8: 0.341125 | X8: 1.2055 | Y8: 4.072375
C9: 46052 | D9: Friday | E9: 1506 | F9: 129 | G9: 7.926 | H9: 2.302 | I9: 0.31 | J9: 0.294 | K9: 0.248 | L9: 1.156 | M9: 3.596 | P9: 45991 | Q9: 19178 | R9: 2110 | S9: 8.8146914 | T9: 2.0165432 | U9: 0.54049383 | V9: 0.33222222 | W9: 0.39135802 | X9: 1.2648148 | Y9: 4.2433333
C10: 46051 | D10: Thursday | E10: 288 | F10: 80 | G10: 9.012 | H10: 2.362 | I10: 0.304 | J10: 0.362 | K10: 1.546 | L10: 1.46 | M10: 2.966 | P10: 45961 | Q10: 16628 | R10: 1921 | S10: 8.6252778 | T10: 3.0390741 | U10: 0.34601852 | V10: 0.20009259 | W10: 0.24981481 | X10: 1.2559259 | Y10: 3.5203704
C11: 46050 | D11: Wednesday | E11: 1595 | F11: 169 | G11: 7.848 | H11: 2.566 | I11: 0.346 | J11: 0.312 | K11: 0.202 | L11: 1.21 | M11: 3.186 | P11: 45930 | Q11: 13444 | R11: 1641 | S11: 8.6389691 | T11: 2.375567 | U11: 0.26381443 | V11: 0.33247423 | W11: 0.24536082 | X11: 1.2196907 | Y11: 4.1845361
C12: 46049 | D12: Tuesday | E12: 1659 | F12: 235 | G12: 8.816 | H12: 2.866 | I12: 0.466 | J12: 0.39 | K12: 0 | L12: 1.304 | M12: 3.758 | P12: 45900 | Q12: 11715 | R12: 1328 | S12: 8.7753125 | T12: 1.3819792 | U12: 0.19458333 | V12: 0.24125 | W12: 0.5165625 | X12: 1.2847917 | Y12: 5.124375
C13: 46048 | D13: Monday | E13: 1481 | F13: 153 | G13: 8.854 | H13: 2.286 | I13: 0.392 | J13: 0.288 | K13: 0.194 | L13: 1.296 | M13: 4.388 | P13: 45869 | Q13: 13495 | R13: 1445 | S13: 8.6698039 | T13: 1.1633333 | U13: 0.2177451 | V13: 0.25960784 | W13: 0.31156863 | X13: 1.1983333 | Y13: 5.4922549
C14: 46045 | D14: Friday | E14: 257 | F14: 77 | G14: 9.1 | H14: 2.64 | I14: 0.3325 | J14: 0.35 | K14: 0.3625 | L14: 1.575 | M14: 3.835 | P14: 45838 | Q14: 12826 | R14: 1312 | S14: 8.3987912 | T14: 1.2889011 | U14: 0.2521978 | V14: 0.31879121 | W14: 0.27582418 | X14: 1.0885714 | Y14: 5.1435165
C15: 46044 | D15: Thursday | E15: 1375 | F15: 83 | G15: 8.96 | H15: 1.926 | I15: 0.116 | J15: 0.238 | K15: 1.586 | L15: 1.352 | M15: 3.72 | P15: 45808 | Q15: 15346 | R15: 1548 | S15: 8.590885 | T15: 1.1486726 | U15: 0.19982301 | V15: 0.23212389 | W15: 0.26707965 | X15: 1.2180531 | Y15: 5.5012389
C16: 46043 | D16: Wednesday | E16: 1689 | F16: 182 | G16: 8.996 | H16: 3.006 | I16: 0.39 | J16: 0.378 | K16: 0.958 | L16: 1.436 | M16: 2.802 | P16: 45777 | Q16: 16926 | R16: 1576 | S16: 8.6095 | T16: 1.0612 | U16: 0.1673 | V16: 0.2219 | W16: 0.2805 | X16: 1.1875 | Y16: 5.6498
C17: 46042 | D17: Tuesday | E17: 410 | F17: 129 | G17: 8.856 | H17: 3.636 | I17: 0.514 | J17: 0.426 | K17: 0.042 | L17: 1.3 | M17: 2.896 | P17: 45747 | Q17: 17692 | R17: 1437 | S17: 8.6172368 | T17: 1.3856579 | U17: 0.16276316 | V17: 0.24894737 | W17: 0.30973684 | X17: 1.1594737 | Y17: 5.3068421
... C19: 46037 | D19: Thursday | E19: 967 | F19: 119 | G19: 9.0325 | H19: 2.4425 | I19: 0.355 | J19: 0.4275 | K19: 1.4175 | L19: 1.4775 | M19: 2.9075 | P19: 45688 | Q19: 20343 | R19: 1911 | S19: 8.7367273 | T19: 1.4046364 | U19: 0.25263636 | V19: 0.27854545 | W19: 0.539 | X19: 1.3459091 | Y19: 4.8787273
C20: 46036 | D20: Wednesday | E20: 1490 | F20: 136 | G20: 7.986 | H20: 2.302 | I20: 0.234 | J20: 0.332 | K20: 0.194 | L20: 1.096 | M20: 3.802 | P20: Grand Total | Q20: 223571 | R20: 23393 | S20: 8.6354792 | T20: 1.7268051 | U20: 0.26301118 | V20: 0.28310703 | W20: 0.35622204 | X20: 1.2319569 | Y20: 4.7473323
C21: 46035 | D21: Tuesday | E21: 1639 | F21: 217 | G21: 9.056 | H21: 2.946 | I21: 0.28 | J21: 0.444 | K21: 0.61 | L21: 1.452 | M21: 3.316
C22: 46034 | D22: Monday | E22: 1449 | F22: 111 | G22: 8.852 | H22: 2.334 | I22: 0.218 | J22: 0.3 | K22: 0.108 | L22: 1.312 | M22: 4.572
C23: 46031 | D23: Friday | E23: 1598 | F23: 151 | G23: 8.852 | H23: 2.528 | I23: 0.252 | J23: 0.424 | K23: 0.102 | L23: 1.392 | M23: 4.144
C24: 46030 | D24: Thursday | E24: 236 | F24: 87 | G24: 8.85 | H24: 2.502 | I24: 0.28 | J24: 0.388 | K24: 1.374 | L24: 1.284 | M24: 2.934
C25: 46029 | D25: Wednesday | E25: 1557 | F25: 212 | G25: 8.83 | H25: 2.726 | I25: 0.4 | J25: 0.434 | K25: 0 | L25: 1.308 | M25: 3.95
C26: 46028 | D26: Tuesday | E26: 255 | F26: 93 | G26: 7.572 | H26: 2.436 | I26: 0.172 | J26: 0.41 | K26: 0 | L26: 1.018 | M26: 3.532
C27: 46027 | D27: Monday | E27: 1480 | F27: 171 | G27: 8.4825 | H27: 2.6 | I27: 0.4575 | J27: 0.4125 | K27: 0.1925 | L27: 1.44 | M27: 3.375
C28: 46024 | D28: Friday | E28: 1078 | F28: 117 | G28: 8.6933333 | H28: 2.87 | I28: 0.25 | J28: 0.53666667 | K28: 0 | L28: 1.0966667 | M28: 3.9266667
C29: 46021 | D29: Tuesday | E29: 39 | F29: 37 | G29: 5.99 | H29: 2.495 | I29: 0.005 | J29: 0.17 | K29: 0 | L29: 0.415 | M29: 2.895
C30: 46020 | D30: Monday | E30: 47 | F30: 33 | G30: 6.005 | H30: 1.7 | I30: 0.005 | J30: 0.065 | K30: 0 | L30: 0.49 | M30: 3.745
C31: 46014 | D31: Tuesday | E31: 239 | F31: 85 | G31: 7.78 | H31: 2.26 | I31: 0.2925 | J31: 0.465 | K31: 0 | L31: 1.15 | M31: 3.5925
C32: 46013 | D32: Monday | E32: 1266 | F32: 110 | G32: 8.02 | H32: 2.27 | I32: 0.2275 | J32: 0.3475 | K32: 0.3 | L32: 1.2725 | M32: 3.575
... C276: 45659 | D276: Thursday | E276: 167 | F276: 161 | G276: 9.0575 | H276: 2.9325 | I276: 0.7525 | J276: 0.345 | K276: 0.21 | L276: 1.4725 | M276: 3.25
D277: (blank) | E277: 841 | F277: 0
C278: Grand Total | E278: 223571 | F278: 23393 | G278: 8.6354792 | H278: 1.7268051 | I278: 0.26301118 | J278: 0.28310703 | K278: 0.35622204 | L278: 1.2319569 | M278: 4.7473323

Sheet Summary
C3: Monthly Agent Efficiency
C5: =Pivots!P5 -> Call_month | D5: Total Dials | E5: Total Connected | F5: Avg Prod Hrs | G5: Call Hrs | H5: Email Hrs | I5: Wrap Hrs | J5: Meeting Hrs | K5: Break hrs | L5: Idle Hrs | M5: Occupancy %age | N5: Idle %age | O5: Break %age
C6: =Pivots!P6 -> 46081 | D6: =Pivots!Q6 -> 4767 | E6: =Pivots!R6 -> 559 | F6: =Pivots!S6 -> 8.8638462 | G6: =Pivots!T6 -> 3.1761538 | H6: =Pivots!U6 -> 0.40076923 | I6: =Pivots!V6 -> 0.37153846 | J6: =Pivots!W6 -> 0.076153846 | ... L6: =Pivots!Y6 -> 3.4915385 | M6: =SUM(G6:J6)/F6 -> 0.45404842 | N6: =L6/F6 -> 0.39390784 | O6: =K6/F6 -> 0.15082878
C7: =Pivots!P7 -> 46053 | D7: =Pivots!Q7 -> 22226 | E7: =Pivots!R7 -> 2734 | F7: =Pivots!S7 -> 8.6537634 | G7: =Pivots!T7 -> 2.5906452 | H7: =Pivots!U7 -> 0.32010753 | I7: =Pivots!V7 -> 0.37236559 | J7: =Pivots!W7 -> 0.47612903 | ... L7: =Pivots!Y7 -> 3.5693548 | M7: =SUM(G7:J7)/F7 -> 0.43440606 | N7: =L7/F7 -> 0.41246272 | O7: =K7/F7 -> 0.1507828
C8: =Pivots!P8 -> 46022 | D8: =Pivots!Q8 -> 20515 | E8: =Pivots!R8 -> 2272 | F8: =Pivots!S8 -> 8.425625 | G8: =Pivots!T8 -> 2.092625 | H8: =Pivots!U8 -> 0.31475 | I8: =Pivots!V8 -> 0.385625 | J8: =Pivots!W8 -> 0.341125 | ... L8: =Pivots!Y8 -> 4.072375 | M8: =SUM(G8:J8)/F8 -> 0.37197537 | N8: =L8/F8 -> 0.4833321 | O8: =K8/F8 -> 0.14307544
C9: =Pivots!P9 -> 45991 | D9: =Pivots!Q9 -> 19178 | E9: =Pivots!R9 -> 2110 | F9: =Pivots!S9 -> 8.8146914 | G9: =Pivots!T9 -> 2.0165432 | H9: =Pivots!U9 -> 0.54049383 | I9: =Pivots!V9 -> 0.33222222 | J9: =Pivots!W9 -> 0.39135802 | ... L9: =Pivots!Y9 -> 4.2433333 | M9: =SUM(G9:J9)/F9 -> 0.37217608 | N9: =L9/F9 -> 0.4813933 | O9: =K9/F9 -> 0.1434894
C10: =Pivots!P10 -> 45961 | D10: =Pivots!Q10 -> 16628 | E10: =Pivots!R10 -> 1921 | F10: =Pivots!S10 -> 8.6252778 | G10: =Pivots!T10 -> 3.0390741 | H10: =Pivots!U10 -> 0.34601852 | I10: =Pivots!V10 -> 0.20009259 | J10: =Pivots!W10 -> 0.24981481 | ... L10: =Pivots!Y10 -> 3.5203704 | M10: =SUM(G10:J10)/F10 -> 0.44462336 | N10: =L10/F10 -> 0.40814574 | O10: =K10/F10 -> 0.14560991
C11: =Pivots!P11 -> 45930 | D11: =Pivots!Q11 -> 13444 | E11: =Pivots!R11 -> 1641 | F11: =Pivots!S11 -> 8.6389691 | G11: =Pivots!T11 -> 2.375567 | H11: =Pivots!U11 -> 0.26381443 | I11: =Pivots!V11 -> 0.33247423 | J11: =Pivots!W11 -> 0.24536082 | ... L11: =Pivots!Y11 -> 4.1845361 | M11: =SUM(G11:J11)/F11 -> 0.37240746 | N11: =L11/F11 -> 0.4843791 | O11: =K11/F11 -> 0.14118475
C12: =Pivots!P12 -> 45900 | D12: =Pivots!Q12 -> 11715 | E12: =Pivots!R12 -> 1328 | F12: =Pivots!S12 -> 8.7753125 | G12: =Pivots!T12 -> 1.3819792 | H12: =Pivots!U12 -> 0.19458333 | I12: =Pivots!V12 -> 0.24125 | J12: =Pivots!W12 -> 0.5165625 | ... L12: =Pivots!Y12 -> 5.124375 | M12: =SUM(G12:J12)/F12 -> 0.26601617 | N12: =L12/F12 -> 0.58395356 | O12: =K12/F12 -> 0.14640979
C13: =Pivots!P13 -> 45869 | D13: =Pivots!Q13 -> 13495 | E13: =Pivots!R13 -> 1445 | F13: =Pivots!S13 -> 8.6698039 | G13: =Pivots!T13 -> 1.1633333 | H13: =Pivots!U13 -> 0.2177451 | I13: =Pivots!V13 -> 0.25960784 | J13: =Pivots!W13 -> 0.31156863 | ... L13: =Pivots!Y13 -> 5.4922549 | M13: =SUM(G13:J13)/F13 -> 0.22517867 | N13: =L13/F13 -> 0.6334924 | O13: =K13/F13 -> 0.1382192
C14: =Pivots!P14 -> 45838 | D14: =Pivots!Q14 -> 12826 | E14: =Pivots!R14 -> 1312 | F14: =Pivots!S14 -> 8.3987912 | G14: =Pivots!T14 -> 1.2889011 | H14: =Pivots!U14 -> 0.2521978 | I14: =Pivots!V14 -> 0.31879121 | J14: =Pivots!W14 -> 0.27582418 | ... L14: =Pivots!Y14 -> 5.1435165 | M14: =SUM(G14:J14)/F14 -> 0.25428829 | N14: =L14/F14 -> 0.61241152 | O14: =K14/F14 -> 0.12961049
C15: =Pivots!P15 -> 45808 | D15: =Pivots!Q15 -> 15346 | E15: =Pivots!R15 -> 1548 | F15: =Pivots!S15 -> 8.590885 | G15: =Pivots!T15 -> 1.1486726 | H15: =Pivots!U15 -> 0.19982301 | I15: =Pivots!V15 -> 0.23212389 | J15: =Pivots!W15 -> 0.26707965 | ... L15: =Pivots!Y15 -> 5.5012389 | M15: =SUM(G15:J15)/F15 -> 0.21507669 | N15: =L15/F15 -> 0.64035765 | O15: =K15/F15 -> 0.14178436
C16: =Pivots!P16 -> 45777 | D16: =Pivots!Q16 -> 16926 | E16: =Pivots!R16 -> 1576 | F16: =Pivots!S16 -> 8.6095 | G16: =Pivots!T16 -> 1.0612 | H16: =Pivots!U16 -> 0.1673 | I16: =Pivots!V16 -> 0.2219 | J16: =Pivots!W16 -> 0.2805 | ... L16: =Pivots!Y16 -> 5.6498 | M16: =SUM(G16:J16)/F16 -> 0.20104536 | N16: =L16/F16 -> 0.65622858 | O16: =K16/F16 -> 0.13792903
C17: =Pivots!P17 -> 45747 | D17: =Pivots!Q17 -> 17692 | E17: =Pivots!R17 -> 1437 | F17: =Pivots!S17 -> 8.6172368 | G17: =Pivots!T17 -> 1.3856579 | H17: =Pivots!U17 -> 0.16276316 | I17: =Pivots!V17 -> 0.24894737 | J17: =Pivots!W17 -> 0.30973684 | ... L17: =Pivots!Y17 -> 5.3068421 | M17: =SUM(G17:J17)/F17 -> 0.24452215 | N17: =L17/F17 -> 0.61584034 | O17: =K17/F17 -> 0.13455284
... C19: =Pivots!P19 -> 45688 | D19: =Pivots!Q19 -> 20343 | E19: =Pivots!R19 -> 1911 | F19: =Pivots!S19 -> 8.7367273 | G19: =Pivots!T19 -> 1.4046364 | H19: =Pivots!U19 -> 0.25263636 | I19: =Pivots!V19 -> 0.27854545 | J19: =Pivots!W19 -> 0.539 | ... L19: =Pivots!Y19 -> 4.8787273 | M19: =SUM(G19:J19)/F19 -> 0.28326605 | N19: =L19/F19 -> 0.55841588 | O19: =K19/F19 -> 0.15405186
C22: Metrics | D22: State | E22: Reason
C23: Call hrs | D23: On Call
D24: On Voicemail
D25: Not Ready | E25: Outbound Calls - Manual
C26: Email Hrs | D26: Not Ready | E26: Email
C27: Wrap Hrs | D27: After Call Work
D28: Not Ready | E28: Extended Research
E29: Tech Issue
E30: Wrap up
E31: Task Completion
E32: System
C33: Meeting Hrs | D33: Not Ready | E33: Team Meeting
E34: Meeting
C35: Break Hrs | D35: Not Ready | E35: Appointment
E36: Break
E37: Lunch
C38: Idle Hrs | D38: Ready

Sheet State and reason 
A1: STATE | B1: REASON_CODE
A2: Logout | B2: Meal
A3: Not Ready | B3: Not Ready
A4: Ready | E4: STATE | F4: REASON_CODE
A5: Not Ready | B5: Break | E5: After Call Work | F5: (blank)
A6: On Hold | E6: DID Ringing | F6: (blank)
A7: Logout | B7: Forced | E7: Login | F7: (blank)
A8: Login | E8: Logout | F8: End Shift
A9: On Voicemail | F9: Forced
A10: Not Ready | B10: Training | F10: Logout
A11: Not Ready | B11: Outbound Calls - Manual | F11: Meal
A12: Not Ready | B12: System | F12: No Reason
A13: Not Ready | B13: Appointment | F13: System
A14: Logout | B14: Logout | F14: (blank)
A15: Not Ready | B15: Meeting | E15: Not Ready | F15: Appointment
A16: Not Ready | B16: Tech Issues | F16: Break
A17: Not Ready | B17: Extended Research | F17: Email
A18: Not Ready | B18: Wrap-Up | F18: Extended Research
A19: Not Ready | B19: SMS | F19: Forced
A20: On Call | F20: Lunch
A21: After Call Work | F21: Meeting
A22: DID Ringing | F22: No Reason
A23: On Park | F23: Not Ready
A24: Logout | B24: System | F24: Outbound Calls - Manual
A25: Not Ready | B25: Task Completion | F25: SMS
A26: Not Ready | B26: No Reason | F26: System
A27: Not Ready | B27: Forced | F27: Task Completion
A28: Not Ready | B28: Team Meeting | F28: Team Meeting
A29: Logout | B29: No Reason | F29: Tech Issues
A30: Not Ready | B30: Email | F30: Training
A31: Ringing | F31: Wrap-Up
A32: Logout | B32: End Shift | E32: On Call | F32: (blank)
A33: Not Ready | B33: Lunch | E33: On Hold | F33: (blank)
A34: Logout | E34: On Park | F34: (blank)
E35: On Voicemail | F35: (blank)
E36: Ready | F36: (blank)
E37: Ringing | F37: (blank)
E38: Grand Total
